<?xml version="1.0"?>
<robot xmlns:xacro="http://www.ros.org/wiki/xacro" name="urdf_tutorial">

    <!-- COLOR -->
    <material name="white">
        <color rgba="1 1 1 1" />
    </material>

    <material name="blue">
        <color rgba="0 0 1 1"/>
    </material>

    <material name="black">
        <color rgba="0 0 0 1"/>
    </material>

    <material name="red">
        <color rgba="1 0 0 1"/>
    </material>

    <!-- BASE LINK -->
    <link name="base_link">
    </link>

    <!-- BODY LINK -->
    <joint name="body_joint" type="fixed">
        <parent link="base_link"/>
        <child link="body"/>
        <origin xyz="-0.12 0 0"/>
    </joint>

    <link name="body">
        <visual>
            <origin xyz="0.1 0 0.03"/>
            <geometry>
                <box size="0.2 0.1 0.06"/>
            </geometry>
            <material name="white"/>
        </visual>
        <collision>
            <origin xyz="0.1 0 0.03"/>
            <geometry>
                <box size="0.2 0.1 0.06"/>
            </geometry>
        </collision>
    </link>

    <!-- LEFT WHEEL LINK -->
    <joint name="left_wheel_joint" type="continuous">
        <parent link="base_link"/>
        <child link="left_wheel"/>
        <origin xyz="0 0.065 0" rpy="-${pi/2} 0 0" />
        <axis xyz="0 0 1"/>
    </joint>

    <link name="left_wheel">
        <visual>
            <geometry>
                <cylinder radius="0.03" length="0.03"/>
            </geometry>
            <material name="blue"/>
        </visual>
        <collision>
            <geometry>
                <cylinder radius="0.03" length="0.03"/>
            </geometry>
        </collision>
    </link>

    <!-- RIGHT WHEEL LINK -->
    <joint name="right_wheel_joint" type="continuous">
        <parent link="base_link"/>
        <child link="right_wheel"/>
        <origin xyz="0 -0.065 0" rpy="${pi/2} 0 0" />
        <axis xyz="0 0 -1"/>
    </joint>

    <link name="right_wheel">
        <visual>
            <geometry>
                <cylinder radius="0.03" length="0.03"/>
            </geometry>
            <material name="blue"/>
        </visual>
        <collision>
            <geometry>
                <cylinder radius="0.03" length="0.03"/>
            </geometry>
        </collision>
    </link>

    <!-- CASTER WHEEL LINK -->
    <joint name="caster_wheel_joint" type="fixed">
        <parent link="body"/>
        <child link="caster_wheel"/>
        <origin xyz="0.03 0 0"/>
    </joint>

    <link name="caster_wheel">
        <visual>
            <geometry>
                <sphere radius="0.03"/>
            </geometry>
            <material name="black"/>
        </visual>
        <collision>
            <geometry>
                <sphere radius="0.03"/>
            </geometry>
        </collision>
    </link>

    <!-- CAMERA -->
    <joint name="camera_joint" type="fixed">
        <parent link="body"/>
        <child link="camera_link"/>
        <origin xyz="0.20 0 0.03" rpy="0 0 0"/>
    </joint>

    <link name="camera_link">
        <visual>
            <geometry>
                <box size="0.01 0.03 0.03"/>
            </geometry>
            <material name="red"/>
        </visual>
        <collision>
            <geometry>
                <box size="0.01 0.03 0.03"/>
            </geometry>
        </collision>
    </link>

    <joint name="camera_optical_joint" type="fixed">
        <parent link="camera_link"/>
        <child link="camera_link_optical"/>
        <origin xyz="0 0 0" rpy="${-pi/2} 0 ${-pi/2}"/>
    </joint>

    <link name="camera_link_optical">
    </link>

</robot>
